<?xml version="1.0"?>

<root xmlns:xi="http://www.w3.org/2001/XInclude"
	xmlns:gazebo="http://playerstage.sourceforge.net/gazebo/xmlschema/#gz"
    xmlns:model="http://playerstage.sourceforge.net/gazebo/xmlschema/#model"
	xmlns:sensor="http://playerstage.sourceforge.net/gazebo/xmlschema/#sensor"
	xmlns:body="http://playerstage.sourceforge.net/gazebo/xmlschema/#body"
    xmlns:geom="http://playerstage.sourceforge.net/gazebo/xmlschema/#geom"
    xmlns:joint="http://playerstage.sourceforge.net/gazebo/xmlschema/#joint"
	xmlns:controller="http://playerstage.sourceforge.net/gazebo/xmlschema/#controller"
	xmlns:interface="http://playerstage.sourceforge.net/gazebo/xmlschema/#interface"
	xmlns:rendering="http://playerstage.sourceforge.net/gazebo/xmlschema/#rendering"
    xmlns:renderable="http://playerstage.sourceforge.net/gazebo/xmlschema/#renderable"
    xmlns:physics="http://playerstage.sourceforge.net/gazebo/xmlschema/#physics"
	xmlns:xacro="http://www.ros.org/wiki/xacro">

	<xacro:property name="camColor" value="255 0 0 1" />

	<xacro:macro name="armMount_link" params="base_parent">
		<link name="nano_arm_mount">
			<visual>
				<geometry>
					<mesh
						filename="package://ada_description/meshes/camera/2023_03_09_nanoArmMount.stl"/>
				</geometry>
				<material name="abs">
					<color rgba="${camColor}" />
				</material>
			</visual>
		</link>

	</xacro:macro>

	<xacro:macro name="armMount_joint">
		<joint name="nano_arm_mount_to_world" type="continuous">
			<parent link="base_parent"/>
			<child link="nano_arm_mount"/>
			<axis xyz="0 0 1"/>
		</joint>
	</xacro:macro>


</root>