<?xml version="1.0" ?>
<!-- =================================================================================== -->
<!-- |    This document was autogenerated by xacro from /home/ekgordon/Workspace/cal_ws/src/ada_ros2/ada_description/urdf/ada.xacro | -->
<!-- |    EDITING THIS FILE BY HAND IS NOT RECOMMENDED                                 | -->
<!-- =================================================================================== -->
<robot name="ada" xmlns:body="http://playerstage.sourceforge.net/gazebo/xmlschema/#body" xmlns:controller="http://playerstage.sourceforge.net/gazebo/xmlschema/#controller" xmlns:gazebo="http://playerstage.sourceforge.net/gazebo/xmlschema/#gz" xmlns:geom="http://playerstage.sourceforge.net/gazebo/xmlschema/#geom" xmlns:interface="http://playerstage.sourceforge.net/gazebo/xmlschema/#interface" xmlns:joint="http://playerstage.sourceforge.net/gazebo/xmlschema/#joint" xmlns:model="http://playerstage.sourceforge.net/gazebo/xmlschema/#model" xmlns:physics="http://playerstage.sourceforge.net/gazebo/xmlschema/#physics" xmlns:renderable="http://playerstage.sourceforge.net/gazebo/xmlschema/#renderable" xmlns:rendering="http://playerstage.sourceforge.net/gazebo/xmlschema/#rendering" xmlns:sensor="http://playerstage.sourceforge.net/gazebo/xmlschema/#sensor" xmlns:xi="http://www.w3.org/2001/XInclude">
    <material name="aluminum">
        <color rgba="0.4 0.4 0.4 1" />
    </material>
    <material name="plastic">
        <color rgba="0.1 0.1 0.1 1" />
    </material>
    <!-- links      		mesh_no
   base           		0
   shoulder       		1
   arm            		2
   forearm        		3
   wrist          		4
   arm_mico       		5
   arm_half1 (7dof)		6
   arm_half2 (7dof)		7
   wrist_spherical_1  8
   wrist_spherical_2  9

   hand 3 finger  		55
   hand_2finger   		56
   finger_proximal		57
   finger_distal      58
-->
    <!-- links      		mesh_no
   base           		0
   shoulder       		1
   arm            		2
   forearm        		3
   wrist          		4
   arm_mico       		5
   arm_half1 (7dof)		6
   arm_half2 (7dof)		7
   wrist_spherical_1  8
   wrist_spherical_2  9

   hand 3 finger  		55
   hand_2finger   		56
   finger_proximal		57
   finger_distal      58
-->
    <link name="root" />
    <!-- ros_control plugin -->
    <gazebo>
        <plugin filename="libgazebo_ros_control.so" name="gazebo_ros_control">
            <robotNamespace>j2n6s200</robotNamespace>
            <robotSimType>gazebo_ros_control/DefaultRobotHWSim</robotSimType>
            <legacyModeNS>true</legacyModeNS>
        </plugin>
    </gazebo>
    <link name="j2n6s200_link_base">
        <visual>
            <geometry>
                <mesh filename="package://ada_description/meshes/base.dae" />
            </geometry>
            <material name="carbon_fiber">
                <color rgba="0.792156862745098 0.819607843137255 0.933333333333333 1" />
            </material>
        </visual>
        <collision>
            <geometry>
                <mesh filename="package://ada_description/meshes/base.dae" />
            </geometry>
        </collision>
        <inertial>
            <mass value="0.46784" />
            <origin rpy="0 0 0" xyz="0 0 0.1255" />
            <inertia ixx="0.000951270861568" ixy="0" ixz="0" iyy="0.000951270861568" iyz="0" izz="0.00037427200000000004" />
        </inertial>
    </link>
    <joint name="j2n6s200_joint_base" type="fixed">
        <parent link="root" />
        <child link="j2n6s200_link_base" />
        <axis xyz="0 0 0" />
        <origin rpy="0 0 0" xyz="0 0 0" />
        <dynamics damping="0.0" friction="0.0" />
    </joint>
    <link name="j2n6s200_link_1">
        <visual>
            <geometry>
                <mesh filename="package://ada_description/meshes/shoulder.dae" />
            </geometry>
            <material name="carbon_fiber">
                <color rgba="0.792156862745098 0.819607843137255 0.933333333333333 1" />
            </material>
        </visual>
        <visual>
            <geometry>
                <mesh filename="package://ada_description/meshes/ring_big.dae" />
            </geometry>
        </visual>
        <collision>
            <geometry>
                <mesh filename="package://ada_description/meshes/shoulder.dae" />
            </geometry>
        </collision>
        <inertial>
            <mass value="0.7477" />
            <origin xyz="0 -0.002 -0.0605" rpy="0 0 0" />
            <inertia ixx="0.0015203172520400004" ixy="0" ixz="0" iyy="0.0015203172520400004" iyz="0" izz="0.00059816" />
        </inertial>
    </link>
    <joint name="j2n6s200_joint_1" type="continuous">
        <parent link="j2n6s200_link_base" />
        <child link="j2n6s200_link_1" />
        <axis xyz="0 0 1" />
        <limit effort="40" velocity="0.6283185307179586" />
        <origin rpy="0 3.141592653589793 0" xyz="0 0 0.15675" />
        <dynamics damping="0.0" friction="0.0" />
    </joint>
    <transmission name="j2n6s200_joint_1_trans">
        <type>transmission_interface/SimpleTransmission</type>
        <joint name="j2n6s200_joint_1">
            <hardwareInterface>hardware_interface/EffortJointInterface</hardwareInterface>
        </joint>
        <actuator name="j2n6s200_joint_1_actuator">
            <hardwareInterface>hardware_interface/EffortJointInterface</hardwareInterface>
            <mechanicalReduction>160</mechanicalReduction>
        </actuator>
    </transmission>
    <!--For torque sensing in simulation-->
    <gazebo reference="j2n6s200_joint_1">
        <provideFeedback>true</provideFeedback>
    </gazebo>
    <gazebo>
        <plugin filename="libgazebo_ros_ft_sensor.so" name="ft_sensor">
            <updateRate>30.0</updateRate>
            <topicName>j2n6s200_joint_1_ft_sensor_topic</topicName>
            <jointName>j2n6s200_joint_1</jointName>
        </plugin>
    </gazebo>
    <link name="j2n6s200_link_2">
        <visual>
            <geometry>
                <mesh filename="package://ada_description/meshes/arm.dae" />
            </geometry>
            <material name="carbon_fiber">
                <color rgba="0.792156862745098 0.819607843137255 0.933333333333333 1" />
            </material>
        </visual>
        <visual>
            <geometry>
                <mesh filename="package://ada_description/meshes/ring_big.dae" />
            </geometry>
        </visual>
        <collision>
            <geometry>
                <mesh filename="package://ada_description/meshes/arm.dae" />
            </geometry>
        </collision>
        <inertial>
            <mass value="0.99" />
            <origin xyz="0 -0.2065 -0.01" rpy="0 0 0" />
            <inertia ixx="0.010502207990999999" ixy="0" ixz="0" iyy="0.0007920000000000001" iyz="0" izz="0.010502207990999999" />
        </inertial>
    </link>
    <joint name="j2n6s200_joint_2" type="revolute">
        <parent link="j2n6s200_link_1" />
        <child link="j2n6s200_link_2" />
        <axis xyz="0 0 1" />
        <limit effort="80" lower="0.8203047484373349" upper="5.462880558742252" velocity="0.6283185307179586" />
        <origin rpy="-1.5707963267948966 0 3.141592653589793" xyz="0 0.0016 -0.11875" />
        <dynamics damping="0.0" friction="0.0" />
    </joint>
    <transmission name="j2n6s200_joint_2_trans">
        <type>transmission_interface/SimpleTransmission</type>
        <joint name="j2n6s200_joint_2">
            <hardwareInterface>hardware_interface/EffortJointInterface</hardwareInterface>
        </joint>
        <actuator name="j2n6s200_joint_2_actuator">
            <hardwareInterface>hardware_interface/EffortJointInterface</hardwareInterface>
            <mechanicalReduction>160</mechanicalReduction>
        </actuator>
    </transmission>
    <!--For torque sensing in simulation-->
    <gazebo reference="j2n6s200_joint_2">
        <provideFeedback>true</provideFeedback>
    </gazebo>
    <gazebo>
        <plugin filename="libgazebo_ros_ft_sensor.so" name="ft_sensor">
            <updateRate>30.0</updateRate>
            <topicName>j2n6s200_joint_2_ft_sensor_topic</topicName>
            <jointName>j2n6s200_joint_2</jointName>
        </plugin>
    </gazebo>
    <link name="j2n6s200_link_3">
        <visual>
            <geometry>
                <mesh filename="package://ada_description/meshes/forearm.dae" />
            </geometry>
            <material name="carbon_fiber">
                <color rgba="0.792156862745098 0.819607843137255 0.933333333333333 1" />
            </material>
        </visual>
        <visual>
            <geometry>
                <mesh filename="package://ada_description/meshes/ring_big.dae" />
            </geometry>
        </visual>
        <collision>
            <geometry>
                <mesh filename="package://ada_description/meshes/forearm.dae" />
            </geometry>
        </collision>
        <inertial>
            <mass value="0.6763" />
            <origin xyz="0 0.081 -0.0086" rpy="0 0 0" />
            <inertia ixx="0.0014202243190800001" ixy="0" ixz="0" iyy="0.000304335" iyz="0" izz="0.0014202243190800001" />
        </inertial>
    </link>
    <joint name="j2n6s200_joint_3" type="revolute">
        <parent link="j2n6s200_link_2" />
        <child link="j2n6s200_link_3" />
        <axis xyz="0 0 1" />
        <limit effort="40" lower="0.33161255787892263" upper="5.951572749300664" velocity="0.6283185307179586" />
        <origin rpy="0 3.141592653589793 0" xyz="0 -0.410 0" />
        <dynamics damping="0.0" friction="0.0" />
    </joint>
    <transmission name="j2n6s200_joint_3_trans">
        <type>transmission_interface/SimpleTransmission</type>
        <joint name="j2n6s200_joint_3">
            <hardwareInterface>hardware_interface/EffortJointInterface</hardwareInterface>
        </joint>
        <actuator name="j2n6s200_joint_3_actuator">
            <hardwareInterface>hardware_interface/EffortJointInterface</hardwareInterface>
            <mechanicalReduction>160</mechanicalReduction>
        </actuator>
    </transmission>
    <!--For torque sensing in simulation-->
    <gazebo reference="j2n6s200_joint_3">
        <provideFeedback>true</provideFeedback>
    </gazebo>
    <gazebo>
        <plugin filename="libgazebo_ros_ft_sensor.so" name="ft_sensor">
            <updateRate>30.0</updateRate>
            <topicName>j2n6s200_joint_3_ft_sensor_topic</topicName>
            <jointName>j2n6s200_joint_3</jointName>
        </plugin>
    </gazebo>
    <link name="j2n6s200_link_4">
        <visual>
            <geometry>
                <mesh filename="package://ada_description/meshes/wrist.dae" />
            </geometry>
            <material name="carbon_fiber">
                <color rgba="0.792156862745098 0.819607843137255 0.933333333333333 1" />
            </material>
        </visual>
        <visual>
            <geometry>
                <mesh filename="package://ada_description/meshes/ring_small.dae" />
            </geometry>
        </visual>
        <collision>
            <geometry>
                <mesh filename="package://ada_description/meshes/wrist.dae" />
            </geometry>
        </collision>
        <inertial>
            <mass value="0.426367" />
            <origin xyz="0 -0.037 -0.0642" rpy="0 0 0" />
            <inertia ixx="7.734969059999999e-05" ixy="0" ixz="0" iyy="7.734969059999999e-05" iyz="0" izz="0.0001428" />
        </inertial>
    </link>
    <joint name="j2n6s200_joint_4" type="continuous">
        <parent link="j2n6s200_link_3" />
        <child link="j2n6s200_link_4" />
        <axis xyz="0 0 1" />
        <limit effort="20" velocity="0.8377580409572781" />
        <origin rpy="-1.5707963267948966 0 3.141592653589793" xyz="0 0.2073 -0.0114" />
        <dynamics damping="0.0" friction="0.0" />
    </joint>
    <transmission name="j2n6s200_joint_4_trans">
        <type>transmission_interface/SimpleTransmission</type>
        <joint name="j2n6s200_joint_4">
            <hardwareInterface>hardware_interface/EffortJointInterface</hardwareInterface>
        </joint>
        <actuator name="j2n6s200_joint_4_actuator">
            <hardwareInterface>hardware_interface/EffortJointInterface</hardwareInterface>
            <mechanicalReduction>160</mechanicalReduction>
        </actuator>
    </transmission>
    <!--For torque sensing in simulation-->
    <gazebo reference="j2n6s200_joint_4">
        <provideFeedback>true</provideFeedback>
    </gazebo>
    <gazebo>
        <plugin filename="libgazebo_ros_ft_sensor.so" name="ft_sensor">
            <updateRate>30.0</updateRate>
            <topicName>j2n6s200_joint_4_ft_sensor_topic</topicName>
            <jointName>j2n6s200_joint_4</jointName>
        </plugin>
    </gazebo>
    <link name="j2n6s200_link_5">
        <visual>
            <geometry>
                <mesh filename="package://ada_description/meshes/wrist.dae" />
            </geometry>
            <material name="carbon_fiber">
                <color rgba="0.792156862745098 0.819607843137255 0.933333333333333 1" />
            </material>
        </visual>
        <visual>
            <geometry>
                <mesh filename="package://ada_description/meshes/ring_small.dae" />
            </geometry>
        </visual>
        <collision>
            <geometry>
                <mesh filename="package://ada_description/meshes/wrist.dae" />
            </geometry>
        </collision>
        <inertial>
            <mass value="0.426367" />
            <origin xyz="0 -0.037 -0.0642" rpy="0 0 0" />
            <inertia ixx="7.734969059999999e-05" ixy="0" ixz="0" iyy="7.734969059999999e-05" iyz="0" izz="0.0001428" />
        </inertial>
    </link>
    <joint name="j2n6s200_joint_5" type="continuous">
        <parent link="j2n6s200_link_4" />
        <child link="j2n6s200_link_5" />
        <axis xyz="0 0 1" />
        <limit effort="20" velocity="0.8377580409572781" />
        <origin rpy="1.0471975511965976 0 3.141592653589793" xyz="0 -0.03703 -0.06414" />
        <dynamics damping="0.0" friction="0.0" />
    </joint>
    <transmission name="j2n6s200_joint_5_trans">
        <type>transmission_interface/SimpleTransmission</type>
        <joint name="j2n6s200_joint_5">
            <hardwareInterface>hardware_interface/EffortJointInterface</hardwareInterface>
        </joint>
        <actuator name="j2n6s200_joint_5_actuator">
            <hardwareInterface>hardware_interface/EffortJointInterface</hardwareInterface>
            <mechanicalReduction>160</mechanicalReduction>
        </actuator>
    </transmission>
    <!--For torque sensing in simulation-->
    <gazebo reference="j2n6s200_joint_5">
        <provideFeedback>true</provideFeedback>
    </gazebo>
    <gazebo>
        <plugin filename="libgazebo_ros_ft_sensor.so" name="ft_sensor">
            <updateRate>30.0</updateRate>
            <topicName>j2n6s200_joint_5_ft_sensor_topic</topicName>
            <jointName>j2n6s200_joint_5</jointName>
        </plugin>
    </gazebo>
    <link name="j2n6s200_link_6">
        <visual>
            <geometry>
                <mesh filename="package://ada_description/meshes/hand_2finger.dae" />
            </geometry>
            <material name="carbon_fiber">
                <color rgba="0.792156862745098 0.819607843137255 0.933333333333333 1" />
            </material>
        </visual>
        <visual>
            <geometry>
                <mesh filename="package://ada_description/meshes/ring_small.dae" />
            </geometry>
        </visual>
        <collision>
            <geometry>
                <mesh filename="package://ada_description/meshes/hand_2finger.dae" />
            </geometry>
        </collision>
        <inertial>
            <mass value="0.78" />
            <origin xyz="0 0 -0.06" rpy="0 0 0" />
            <inertia ixx="0.00037049851799999997" ixy="0" ixz="0" iyy="0.00037049851799999997" iyz="0" izz="0.0006240000000000001" />
        </inertial>
    </link>
    <joint name="j2n6s200_joint_6" type="continuous">
        <parent link="j2n6s200_link_5" />
        <child link="j2n6s200_link_6" />
        <axis xyz="0 0 1" />
        <limit effort="20" velocity="0.8377580409572781" />
        <origin rpy="1.0471975511965976 0 3.141592653589793" xyz="0 -0.03703 -0.06414" />
        <dynamics damping="0.0" friction="0.0" />
    </joint>
    <transmission name="j2n6s200_joint_6_trans">
        <type>transmission_interface/SimpleTransmission</type>
        <joint name="j2n6s200_joint_6">
            <hardwareInterface>hardware_interface/EffortJointInterface</hardwareInterface>
        </joint>
        <actuator name="j2n6s200_joint_6_actuator">
            <hardwareInterface>hardware_interface/EffortJointInterface</hardwareInterface>
            <mechanicalReduction>160</mechanicalReduction>
        </actuator>
    </transmission>
    <!--For torque sensing in simulation-->
    <gazebo reference="j2n6s200_joint_6">
        <provideFeedback>true</provideFeedback>
    </gazebo>
    <gazebo>
        <plugin filename="libgazebo_ros_ft_sensor.so" name="ft_sensor">
            <updateRate>30.0</updateRate>
            <topicName>j2n6s200_joint_6_ft_sensor_topic</topicName>
            <jointName>j2n6s200_joint_6</jointName>
        </plugin>
    </gazebo>
    <link name="j2n6s200_end_effector" />
    <joint name="j2n6s200_joint_end_effector" type="fixed">
        <parent link="j2n6s200_link_6" />
        <child link="j2n6s200_end_effector" />
        <axis xyz="0 0 0" />
        <origin rpy="3.141592653589793 0 1.5707963267948966" xyz="0 0 -0.1600" />
    </joint>
    <link name="j2n6s200_link_finger_1">
        <visual>
            <geometry>
                <mesh filename="package://ada_description/meshes/finger_proximal.dae" />
            </geometry>
            <material name="carbon_fiber">
                <color rgba="0.792156862745098 0.819607843137255 0.933333333333333 1" />
            </material>
        </visual>
        <collision>
            <geometry>
                <mesh filename="package://ada_description/meshes/finger_proximal.dae" />
            </geometry>
        </collision>
        <inertial>
            <mass value="0.01" />
            <origin xyz="0.022 0 0" rpy="0 0 0" />
            <inertia ixx="7.8999684e-07" ixy="0" ixz="0" iyy="7.8999684e-07" iyz="0" izz="8e-08" />
        </inertial>
    </link>
    <joint name="j2n6s200_joint_finger_1" type="revolute">
        <parent link="j2n6s200_link_6" />
        <child link="j2n6s200_link_finger_1" />
        <axis xyz="0 0 1" />
        <origin rpy="-1.570796327 .649262481663582 1.57079632679490" xyz="-0.0025 0.03095 -0.11482" />
        <limit effort="2" lower="0" upper="1.51" velocity="1" />
    </joint>
    <transmission name="j2n6s200_joint_finger_1_trans">
        <type>transmission_interface/SimpleTransmission</type>
        <joint name="j2n6s200_joint_finger_1">
            <hardwareInterface>hardware_interface/EffortJointInterface</hardwareInterface>
        </joint>
        <actuator name="j2n6s200_joint_finger_1_actuator">
            <hardwareInterface>hardware_interface/EffortJointInterface</hardwareInterface>
            <mechanicalReduction>1</mechanicalReduction>
        </actuator>
    </transmission>
    <link name="j2n6s200_link_finger_tip_1">
        <visual>
            <geometry>
                <mesh filename="package://ada_description/meshes/finger_distal.dae" />
            </geometry>
            <material name="carbon_fiber">
                <color rgba="0.792156862745098 0.819607843137255 0.933333333333333 1" />
            </material>
        </visual>
        <collision>
            <geometry>
                <mesh filename="package://ada_description/meshes/finger_distal.dae" />
            </geometry>
        </collision>
        <inertial>
            <mass value="0.01" />
            <origin xyz="0.022 0 0" rpy="0 0 0" />
            <inertia ixx="7.8999684e-07" ixy="0" ixz="0" iyy="7.8999684e-07" iyz="0" izz="8e-08" />
        </inertial>
    </link>
    <joint name="j2n6s200_joint_finger_tip_1" type="fixed">
        <parent link="j2n6s200_link_finger_1" />
        <child link="j2n6s200_link_finger_tip_1" />
        <axis xyz="0 0 1" />
        <origin rpy="0 0 0" xyz="0.044 -0.003 0" />
        <limit effort="2" lower="0" upper="2" velocity="1" />
    </joint>
    <transmission name="j2n6s200_joint_finger_tip_1_trans">
        <type>transmission_interface/SimpleTransmission</type>
        <joint name="j2n6s200_joint_finger_tip_1">
            <hardwareInterface>hardware_interface/EffortJointInterface</hardwareInterface>
        </joint>
        <actuator name="j2n6s200_joint_finger_tip_1_actuator">
            <hardwareInterface>hardware_interface/EffortJointInterface</hardwareInterface>
            <mechanicalReduction>1</mechanicalReduction>
        </actuator>
    </transmission>
    <link name="j2n6s200_link_finger_2">
        <visual>
            <geometry>
                <mesh filename="package://ada_description/meshes/finger_proximal.dae" />
            </geometry>
            <material name="carbon_fiber">
                <color rgba="0.792156862745098 0.819607843137255 0.933333333333333 1" />
            </material>
        </visual>
        <collision>
            <geometry>
                <mesh filename="package://ada_description/meshes/finger_proximal.dae" />
            </geometry>
        </collision>
        <inertial>
            <mass value="0.01" />
            <origin xyz="0.022 0 0" rpy="0 0 0" />
            <inertia ixx="7.8999684e-07" ixy="0" ixz="0" iyy="7.8999684e-07" iyz="0" izz="8e-08" />
        </inertial>
    </link>
    <joint name="j2n6s200_joint_finger_2" type="revolute">
        <parent link="j2n6s200_link_6" />
        <child link="j2n6s200_link_finger_2" />
        <axis xyz="0 0 1" />
        <origin rpy="-1.570796327 .649262481663582 -1.57079632679490" xyz="-0.0025 -0.03095 -0.11482" />
        <limit effort="2" lower="0" upper="1.51" velocity="1" />
    </joint>
    <transmission name="j2n6s200_joint_finger_2_trans">
        <type>transmission_interface/SimpleTransmission</type>
        <joint name="j2n6s200_joint_finger_2">
            <hardwareInterface>hardware_interface/EffortJointInterface</hardwareInterface>
        </joint>
        <actuator name="j2n6s200_joint_finger_2_actuator">
            <hardwareInterface>hardware_interface/EffortJointInterface</hardwareInterface>
            <mechanicalReduction>1</mechanicalReduction>
        </actuator>
    </transmission>
    <link name="j2n6s200_link_finger_tip_2">
        <visual>
            <geometry>
                <mesh filename="package://ada_description/meshes/finger_distal.dae" />
            </geometry>
            <material name="carbon_fiber">
                <color rgba="0.792156862745098 0.819607843137255 0.933333333333333 1" />
            </material>
        </visual>
        <collision>
            <geometry>
                <mesh filename="package://ada_description/meshes/finger_distal.dae" />
            </geometry>
        </collision>
        <inertial>
            <mass value="0.01" />
            <origin xyz="0.022 0 0" rpy="0 0 0" />
            <inertia ixx="7.8999684e-07" ixy="0" ixz="0" iyy="7.8999684e-07" iyz="0" izz="8e-08" />
        </inertial>
    </link>
    <joint name="j2n6s200_joint_finger_tip_2" type="fixed">
        <parent link="j2n6s200_link_finger_2" />
        <child link="j2n6s200_link_finger_tip_2" />
        <axis xyz="0 0 1" />
        <origin rpy="0 0 0" xyz="0.044 -0.003 0" />
        <limit effort="2" lower="0" upper="2" velocity="1" />
    </joint>
    <transmission name="j2n6s200_joint_finger_tip_2_trans">
        <type>transmission_interface/SimpleTransmission</type>
        <joint name="j2n6s200_joint_finger_tip_2">
            <hardwareInterface>hardware_interface/EffortJointInterface</hardwareInterface>
        </joint>
        <actuator name="j2n6s200_joint_finger_tip_2_actuator">
            <hardwareInterface>hardware_interface/EffortJointInterface</hardwareInterface>
            <mechanicalReduction>1</mechanicalReduction>
        </actuator>
    </transmission>
    <link name="nanoMount">
        <visual>
            <geometry>
                <mesh filename="package://ada_description/meshes/camera/2023_03_09_nanoArmMount.stl" scale="0.001 0.001 0.001" />
            </geometry>
            <material name="abs">
                <color rgba="0.4 0.4 0.4 1" />
            </material>
        </visual>
        <collision>
            <geometry>
                <mesh filename="package://ada_description/meshes/camera/2023_03_09_nanoArmMount.stl" scale="0.001 0.001 0.001" />
            </geometry>
        </collision>
        <inertial>
            <origin rpy="0 0 0" xyz="-0.002400 0.0046958 0.0115245" />
            <mass value="0.008" />
            <inertia ixx="0.001" ixy="0.001" ixz="0.001" iyy="0.001" iyz="0.001" izz="0.001" />
        </inertial>
    </link>
    <joint name="nanoMount_to_world" type="fixed">
        <parent link="j2n6s200_link_6" />
        <child link="nanoMount" />
        <axis xyz="0 0 1" />
        <origin rpy="4.71238898038469 0 4.71238898038469" xyz="0.0165 0 0.0011" />
    </joint>
    <link name="enclosureBottom">
        <visual>
            <geometry>
                <mesh filename="package://ada_description/meshes/camera/2023_03_16_nanoEnclosureBottom.stl" scale="0.001 0.001 0.001" />
            </geometry>
            <material name="abs">
                <color rgba="0.4 0.4 0.4 1" />
            </material>
        </visual>
        <collision>
            <geometry>
                <mesh filename="package://ada_description/meshes/camera/2023_03_16_nanoEnclosureBottom.stl" scale="0.001 0.001 0.001" />
            </geometry>
        </collision>
        <inertial>
            <origin rpy="0 0 0" xyz="0.0546451 0.0472161 0.00043655" />
            <mass value="0.04" />
            <inertia ixx="0.001" ixy="0.001" ixz="0.001" iyy="0.001" iyz="0.001" izz="0.001" />
        </inertial>
    </link>
    <joint name="enclosureBottom_to_nanoMount" type="fixed">
        <parent link="nanoMount" />
        <child link="enclosureBottom" />
        <axis xyz="0 0 1" />
        <origin rpy="0 0 1.5707963267948966" xyz="0.0412 -0.0218 0.026" />
    </joint>
    <link name="nano">
        <visual>
            <geometry>
                <mesh filename="package://ada_description/meshes/camera/2023_03_21_jetsonNano.stl" scale="0.001 0.001 0.001" />
            </geometry>
            <material name="abs">
                <color rgba="0.4 0.4 0.4 1" />
            </material>
        </visual>
        <collision>
            <geometry>
                <mesh filename="package://ada_description/meshes/camera/2023_03_21_jetsonNano.stl" scale="0.001 0.001 0.001" />
            </geometry>
        </collision>
        <inertial>
            <origin rpy="0 0 0" xyz="0.0435615 0.02502709 0.0091247" />
            <mass value="0.142" />
            <inertia ixx="0.001" ixy="0.001" ixz="0.001" iyy="0.001" iyz="0.001" izz="0.001" />
        </inertial>
    </link>
    <joint name="nano_to_enclosureBottom" type="fixed">
        <parent link="enclosureBottom" />
        <child link="nano" />
        <axis xyz="0 0 1" />
        <origin rpy="0 0 0" xyz="0.0105 0.014 -0.0015" />
    </joint>
    <link name="enclosureTop">
        <visual>
            <geometry>
                <mesh filename="package://ada_description/meshes/camera/2023_06_06_nanoEnclosureTopCameraBack.stl" scale="0.001 0.001 0.001" />
            </geometry>
            <material name="abs">
                <color rgba="0.4 0.4 0.4 1" />
            </material>
        </visual>
        <collision>
            <geometry>
                <mesh filename="package://ada_description/meshes/camera/2023_06_06_nanoEnclosureTopCameraBack.stl" scale="0.001 0.001 0.001" />
            </geometry>
        </collision>
        <inertial>
            <origin rpy="0 0 0" xyz="0.04817211 0.03496864 0.02671124" />
            <mass value="0.046" />
            <inertia ixx="0.001" ixy="0.001" ixz="0.001" iyy="0.001" iyz="0.001" izz="0.001" />
        </inertial>
    </link>
    <joint name="enclosureTop_to_enclosureBottom" type="fixed">
        <parent link="enclosureBottom" />
        <child link="enclosureTop" />
        <axis xyz="0 0 1" />
        <origin rpy="0 2.886774582798621 3.141592653589793" xyz="0.009925 0.04099 0.05442" />
    </joint>
    <link name="cameraMount">
        <visual>
            <geometry>
                <mesh filename="package://ada_description/meshes/camera/2023_06_06_cameraBackMount.stl" scale="0.001 0.001 0.001" />
            </geometry>
            <material name="abs">
                <color rgba="0.4 0.4 0.4 1" />
            </material>
        </visual>
        <collision>
            <geometry>
                <mesh filename="package://ada_description/meshes/camera/2023_06_06_cameraBackMount.stl" scale="0.001 0.001 0.001" />
            </geometry>
        </collision>
        <inertial>
            <origin rpy="0 0 0" xyz="0.00272454 0.00000231884 0.00514249" />
            <mass value="0.004" />
            <inertia ixx="0.001" ixy="0.001" ixz="0.001" iyy="0.001" iyz="0.001" izz="0.001" />
        </inertial>
    </link>
    <joint name="cameraMount_to_enclosureTop" type="fixed">
        <parent link="enclosureTop" />
        <child link="cameraMount" />
        <axis xyz="0 0 1" />
        <origin rpy="0 1.5707963267948966 0" xyz="-0.0132 0 -0.022" />
    </joint>
    <!-- camera body, with origin at bottom screw mount -->
    <joint name="uncalibrated_camera_joint" type="fixed">
        <origin rpy="0 -1.5707963267948966 3.141592653589793" xyz="0.006 0 0.013" />
        <parent link="cameraMount" />
        <child link="uncalibrated_camera_bottom_screw_frame" />
    </joint>
    <link name="uncalibrated_camera_bottom_screw_frame" />
    <joint name="uncalibrated_camera_link_joint" type="fixed">
        <origin rpy="0 0 0" xyz="0 0.02 0.0115" />
        <parent link="uncalibrated_camera_bottom_screw_frame" />
        <child link="uncalibrated_camera_link" />
    </joint>
    <link name="uncalibrated_camera_link">
        <visual>
            <origin rpy="1.5707963267948966 0 1.5707963267948966" xyz="0.00987 -0.02 0" />
            <geometry>
                <mesh filename="package://ada_description/meshes/camera/d415.stl" />
            </geometry>
            <material name="aluminum" />
        </visual>
        <collision>
            <origin rpy="0 0 0" xyz="0 -0.02 0" />
            <geometry>
                <box size="0.02005 0.099 0.023" />
            </geometry>
        </collision>
        <inertial>
            <mass value="0.072" />
            <!-- The following are not reliable values, and should not be used for modeling -->
            <origin xyz="0 0 0" rpy="0 0 0" />
            <inertia ixx="0.003881243" ixy="0.0" ixz="0.0" iyy="0.000498940" iyz="0.0" izz="0.003879257" />
        </inertial>
    </link>
    <!-- Hard-coded Extrinsics -->
    <link name="camera_link" />
    <joint name="extrinsics" type="fixed">
        <origin rpy="-0.039 0.100 -0.007" xyz="0.023 0.055 0.005" />
        <parent link="cameraMount" />
        <child link="camera_link" />
    </joint>
    <!-- Copy Realsense in case of simulation -->
    <!--
  <link name="camera_color_optical_frame" />
  <joint name="optical_republish" type="fixed">
    <origin xyz="0.000 -0.015 0.000" rpy="-1.564 0.000 -1.573" />
    <parent link="camera_link" />
    <child link="camera_color_optical_frame" />
  </joint>
  -->
    <link name="FTArmMount">
        <visual>
            <geometry>
                <mesh filename="package://ada_description/meshes/forque/2023_03_09_FTArmMount.stl" scale="0.001 0.001 0.001" />
            </geometry>
            <material name="abs">
                <color rgba="0.4 0.4 0.4 1" />
            </material>
        </visual>
        <collision>
            <geometry>
                <mesh filename="package://ada_description/meshes/forque/2023_03_09_FTArmMount.stl" scale="0.001 0.001 0.001" />
            </geometry>
        </collision>
        <inertial>
            <origin rpy="0 0 0" xyz="0.011184837 -0.024537498 -0.035437509" />
            <mass value="0.0025" />
            <inertia ixx="0.001" ixy="0.001" ixz="0.001" iyy="0.001" iyz="0.001" izz="0.001" />
        </inertial>
    </link>
    <joint name="FTArmMount_to_arm" type="fixed">
        <parent link="j2n6s200_link_6" />
        <child link="FTArmMount" />
        <axis xyz="0 0 1" />
        <origin rpy="1.5707963267948966 0 1.5707963267948966" xyz="0.0065 -0.011 -0.0075" />
    </joint>
    <link name="FTMount">
        <visual>
            <geometry>
                <mesh filename="package://ada_description/meshes/forque/2023_03_09_FTMount.stl" scale="0.001 0.001 0.001" />
            </geometry>
            <material name="abs">
                <color rgba="0.4 0.4 0.4 1" />
            </material>
        </visual>
        <collision>
            <geometry>
                <mesh filename="package://ada_description/meshes/forque/2023_03_09_FTMount.stl" scale="0.001 0.001 0.001" />
            </geometry>
        </collision>
        <inertial>
            <origin rpy="0 0 0" xyz="0.0111797 -0.110193 -0.0384312" />
            <mass value="0.022" />
            <inertia ixx="0.001" ixy="0.001" ixz="0.001" iyy="0.001" iyz="0.001" izz="0.001" />
        </inertial>
    </link>
    <joint name="FTMount_to_world" type="fixed">
        <parent link="FTArmMount" />
        <child link="FTMount" />
        <axis xyz="0 0 1" />
        <origin rpy="0 0 0" xyz="0 0 0" />
    </joint>
    <link name="FT">
        <visual>
            <geometry>
                <mesh filename="package://ada_description/meshes/forque/2023_03_09_wirelessFT.stl" scale="0.001 0.001 0.001" />
            </geometry>
            <material name="abs">
                <color rgba="0.4 0.4 0.4 1" />
            </material>
        </visual>
        <collision>
            <geometry>
                <mesh filename="package://ada_description/meshes/forque/2023_03_09_wirelessFT.stl" scale="0.001 0.001 0.001" />
            </geometry>
        </collision>
        <inertial>
            <origin rpy="0 0 0" xyz="0.0111446 -0.0882070 -0.0544936" />
            <mass value="0.28" />
            <inertia ixx="0.001" ixy="0.001" ixz="0.001" iyy="0.001" iyz="0.001" izz="0.001" />
        </inertial>
    </link>
    <joint name="FT_to_FTMount" type="fixed">
        <parent link="FTMount" />
        <child link="FT" />
        <axis xyz="0 0 1" />
        <origin rpy="0 0 0" xyz="0 0 0" />
    </joint>
    <link name="forkHandle">
        <visual>
            <geometry>
                <mesh filename="package://ada_description/meshes/forque/2023_03_09_forkHandle.stl" scale="0.001 0.001 0.001" />
            </geometry>
            <material name="abs">
                <color rgba="0.4 0.4 0.4 1" />
            </material>
        </visual>
        <collision>
            <geometry>
                <mesh filename="package://ada_description/meshes/forque/2023_03_09_forkHandle.stl" scale="0.001 0.001 0.001" />
            </geometry>
        </collision>
        <inertial>
            <origin rpy="0 0 0" xyz="0.0110024 -0.151715 -0.00934664" />
            <mass value="0.0506" />
            <inertia ixx="0.001" ixy="0.001" ixz="0.001" iyy="0.001" iyz="0.001" izz="0.001" />
        </inertial>
    </link>
    <joint name="forkHandle_to_FTMount" type="fixed">
        <parent link="FTMount" />
        <child link="forkHandle" />
        <axis xyz="0 0 1" />
        <origin rpy="0 0 0" xyz="0 0 0" />
    </joint>
    <link name="forque">
        <visual>
            <geometry>
                <mesh filename="package://ada_description/meshes/forque/ATI-9105-TW-NANO25-E.stl" scale="0.001 0.001 0.001" />
            </geometry>
            <material name="abs">
                <color rgba="0.4 0.4 0.4 1" />
            </material>
        </visual>
        <collision>
            <geometry>
                <mesh filename="package://ada_description/meshes/forque/ATI-9105-TW-NANO25-E.stl" scale="0.001 0.001 0.001" />
            </geometry>
        </collision>
        <inertial>
            <origin rpy="0 0 0" xyz="0.0124692 0.0137169 0.010558" />
            <mass value="0.0634" />
            <inertia ixx="0.001" ixy="0.001" ixz="0.001" iyy="0.001" iyz="0.001" izz="0.001" />
        </inertial>
    </link>
    <joint name="forque_to_forkHandle" type="fixed">
        <parent link="forkHandle" />
        <child link="forque" />
        <axis xyz="0 0 1" />
        <origin rpy="1.5707963267948966 1.0471975511965976 0" xyz="-0.00634 -0.222553 -0.004286" />
    </joint>
    <link name="forkTine">
        <visual>
            <geometry>
                <mesh filename="package://ada_description/meshes/forque/fork_tine.stl" scale="0.001 0.001 0.001" />
            </geometry>
            <material name="abs">
                <color rgba="0.4 0.4 0.4 1" />
            </material>
        </visual>
        <collision>
            <geometry>
                <mesh filename="package://ada_description/meshes/forque/fork_tine.stl" scale="0.001 0.001 0.001" />
            </geometry>
        </collision>
        <inertial>
            <origin rpy="0 0 0" xyz="0.013090 0.0180789 0.0445231" />
            <mass value="0.024" />
            <inertia ixx="0.001" ixy="0.001" ixz="0.001" iyy="0.001" iyz="0.001" izz="0.001" />
        </inertial>
    </link>
    <joint name="forkTine_to_forque" type="fixed">
        <parent link="forque" />
        <child link="forkTine" />
        <axis xyz="0 0 1" />
        <origin rpy="0 3.141592653589793 4.1887902047863905" xyz="-0.0054 0.008 0.093" />
    </joint>
    <link name="forkTip" />
    <joint name="forkTip_to_forkTine" type="fixed">
        <child link="forkTip" />
        <parent link="forkTine" />
        <origin rpy="3.141592653589793 0 0" xyz="0.0135 0.007 0" />
    </joint>
    <link name="FTSensor" />
    <joint name="EE_to_FTSensor" type="fixed">
        <child link="FTSensor" />
        <parent link="j2n6s200_end_effector" />
        <origin rpy="0 0 0" xyz="0.0 0.0 0.092" />
    </joint>
</robot>

