<?xml version="1.0" ?>
<!-- =================================================================================== -->
<!-- |    This document was autogenerated by xacro from src/ada_ros2/ada_description/urdf/ada.xacro | -->
<!-- |    EDITING THIS FILE BY HAND IS NOT RECOMMENDED                                 | -->
<!-- =================================================================================== -->
<robot name="ada" xmlns:body="http://playerstage.sourceforge.net/gazebo/xmlschema/#body" xmlns:controller="http://playerstage.sourceforge.net/gazebo/xmlschema/#controller" xmlns:gazebo="http://playerstage.sourceforge.net/gazebo/xmlschema/#gz" xmlns:geom="http://playerstage.sourceforge.net/gazebo/xmlschema/#geom" xmlns:interface="http://playerstage.sourceforge.net/gazebo/xmlschema/#interface" xmlns:joint="http://playerstage.sourceforge.net/gazebo/xmlschema/#joint" xmlns:model="http://playerstage.sourceforge.net/gazebo/xmlschema/#model" xmlns:physics="http://playerstage.sourceforge.net/gazebo/xmlschema/#physics" xmlns:renderable="http://playerstage.sourceforge.net/gazebo/xmlschema/#renderable" xmlns:rendering="http://playerstage.sourceforge.net/gazebo/xmlschema/#rendering" xmlns:sensor="http://playerstage.sourceforge.net/gazebo/xmlschema/#sensor" xmlns:xi="http://www.w3.org/2001/XInclude">
  <material name="aluminum">
    <color rgba="0.4 0.4 0.4 1"/>
  </material>
  <material name="plastic">
    <color rgba="0.1 0.1 0.1 1"/>
  </material>
  <!-- links      		mesh_no
   base           		0
   shoulder       		1
   arm            		2
   forearm        		3
   wrist          		4
   arm_mico       		5
   arm_half1 (7dof)		6
   arm_half2 (7dof)		7
   wrist_spherical_1  8
   wrist_spherical_2  9

   hand 3 finger  		55
   hand_2finger   		56
   finger_proximal		57
   finger_distal      58
-->
  <!-- links      		mesh_no
   base           		0
   shoulder       		1
   arm            		2
   forearm        		3
   wrist          		4
   arm_mico       		5
   arm_half1 (7dof)		6
   arm_half2 (7dof)		7
   wrist_spherical_1  8
   wrist_spherical_2  9

   hand 3 finger  		55
   hand_2finger   		56
   finger_proximal		57
   finger_distal      58
-->
  <link name="root"/>
  <link name="root_tilt"/>
  <joint name="robot_tilt" type="revolute">
    <origin rpy="0 0 0" xyz="0 0 0"/>
    <child link="root_tilt"/>
    <parent link="root"/>
    <axis xyz="-1 0 0"/>
    <!-- effort copied from j2n6s200 joint 2, velocity is max velocity the wheelchair can tilt,
    lower and upper limits generously encompass the range of the wheelchair's tilt-->
    <limit effort="80" lower="-3.141592653589793" upper="3.141592653589793" velocity="0.15"/>
    <dynamics damping="0.0" friction="0.0"/>
  </joint>
  <!-- ros_control plugin -->
  <gazebo>
    <plugin filename="libgazebo_ros_control.so" name="gazebo_ros_control">
      <robotNamespace>j2n6s200</robotNamespace>
      <robotSimType>gazebo_ros_control/DefaultRobotHWSim</robotSimType>
      <legacyModeNS>true</legacyModeNS>
    </plugin>
  </gazebo>
  <link name="j2n6s200_link_base">
    <visual>
      <geometry>
        <mesh filename="package://ada_description/meshes/base.dae"/>
      </geometry>
      <material name="carbon_fiber">
        <color rgba="0.792156862745098 0.819607843137255 0.933333333333333 1"/>
      </material>
    </visual>
    <collision>
      <geometry>
        <mesh filename="package://ada_description/meshes/base.dae"/>
      </geometry>
    </collision>
    <inertial>
      <mass value="0.46784"/>
      <origin rpy="0 0 0" xyz="0 0 0.1255"/>
      <inertia ixx="0.000951270861568" ixy="0" ixz="0" iyy="0.000951270861568" iyz="0" izz="0.00037427200000000004"/>
    </inertial>
  </link>
  <joint name="j2n6s200_joint_base" type="fixed">
    <parent link="root_tilt"/>
    <child link="j2n6s200_link_base"/>
    <axis xyz="0 0 0"/>
    <origin rpy="0 0 0" xyz="0 0 0"/>
    <dynamics damping="0.0" friction="0.0"/>
  </joint>
  <link name="j2n6s200_link_1">
    <visual>
      <geometry>
        <mesh filename="package://ada_description/meshes/shoulder.dae"/>
      </geometry>
      <material name="carbon_fiber">
        <color rgba="0.792156862745098 0.819607843137255 0.933333333333333 1"/>
      </material>
    </visual>
    <visual>
      <geometry>
        <mesh filename="package://ada_description/meshes/ring_big.dae"/>
      </geometry>
    </visual>
    <collision>
      <geometry>
        <mesh filename="package://ada_description/meshes/shoulder.dae"/>
      </geometry>
    </collision>
    <inertial>
      <mass value="0.7477"/>
      <origin xyz="0 -0.002 -0.0605"/>
      <inertia ixx="0.0015203172520400004" ixy="0" ixz="0" iyy="0.0015203172520400004" iyz="0" izz="0.00059816"/>
    </inertial>
  </link>
  <joint name="j2n6s200_joint_1" type="continuous">
    <parent link="j2n6s200_link_base"/>
    <child link="j2n6s200_link_1"/>
    <axis xyz="0 0 1"/>
    <limit effort="40" velocity="0.6283185307179586"/>
    <origin rpy="0 3.141592653589793 0" xyz="0 0 0.15675"/>
    <dynamics damping="0.0" friction="0.0"/>
  </joint>
  <transmission name="j2n6s200_joint_1_trans">
    <type>transmission_interface/SimpleTransmission</type>
    <joint name="j2n6s200_joint_1">
      <hardwareInterface>hardware_interface/EffortJointInterface</hardwareInterface>
    </joint>
    <actuator name="j2n6s200_joint_1_actuator">
      <hardwareInterface>hardware_interface/EffortJointInterface</hardwareInterface>
      <mechanicalReduction>160</mechanicalReduction>
    </actuator>
  </transmission>
  <!--For torque sensing in simulation-->
  <gazebo reference="j2n6s200_joint_1">
    <provideFeedback>true</provideFeedback>
  </gazebo>
  <gazebo>
    <plugin filename="libgazebo_ros_ft_sensor.so" name="ft_sensor">
      <updateRate>30.0</updateRate>
      <topicName>j2n6s200_joint_1_ft_sensor_topic</topicName>
      <jointName>j2n6s200_joint_1</jointName>
    </plugin>
  </gazebo>
  <link name="j2n6s200_link_2">
    <visual>
      <geometry>
        <mesh filename="package://ada_description/meshes/arm.dae"/>
      </geometry>
      <material name="carbon_fiber">
        <color rgba="0.792156862745098 0.819607843137255 0.933333333333333 1"/>
      </material>
    </visual>
    <visual>
      <geometry>
        <mesh filename="package://ada_description/meshes/ring_big.dae"/>
      </geometry>
    </visual>
    <collision>
      <geometry>
        <mesh filename="package://ada_description/meshes/arm.dae"/>
      </geometry>
    </collision>
    <inertial>
      <mass value="0.99"/>
      <origin xyz="0 -0.2065 -0.01"/>
      <inertia ixx="0.010502207990999999" ixy="0" ixz="0" iyy="0.0007920000000000001" iyz="0" izz="0.010502207990999999"/>
    </inertial>
  </link>
  <joint name="j2n6s200_joint_2" type="revolute">
    <parent link="j2n6s200_link_1"/>
    <child link="j2n6s200_link_2"/>
    <axis xyz="0 0 1"/>
    <limit effort="80" lower="0.8203047484373349" upper="5.462880558742252" velocity="0.6283185307179586"/>
    <origin rpy="-1.5707963267948966 0 3.141592653589793" xyz="0 0.0016 -0.11875"/>
    <dynamics damping="0.0" friction="0.0"/>
  </joint>
  <transmission name="j2n6s200_joint_2_trans">
    <type>transmission_interface/SimpleTransmission</type>
    <joint name="j2n6s200_joint_2">
      <hardwareInterface>hardware_interface/EffortJointInterface</hardwareInterface>
    </joint>
    <actuator name="j2n6s200_joint_2_actuator">
      <hardwareInterface>hardware_interface/EffortJointInterface</hardwareInterface>
      <mechanicalReduction>160</mechanicalReduction>
    </actuator>
  </transmission>
  <!--For torque sensing in simulation-->
  <gazebo reference="j2n6s200_joint_2">
    <provideFeedback>true</provideFeedback>
  </gazebo>
  <gazebo>
    <plugin filename="libgazebo_ros_ft_sensor.so" name="ft_sensor">
      <updateRate>30.0</updateRate>
      <topicName>j2n6s200_joint_2_ft_sensor_topic</topicName>
      <jointName>j2n6s200_joint_2</jointName>
    </plugin>
  </gazebo>
  <link name="j2n6s200_link_3">
    <visual>
      <geometry>
        <mesh filename="package://ada_description/meshes/forearm.dae"/>
      </geometry>
      <material name="carbon_fiber">
        <color rgba="0.792156862745098 0.819607843137255 0.933333333333333 1"/>
      </material>
    </visual>
    <visual>
      <geometry>
        <mesh filename="package://ada_description/meshes/ring_big.dae"/>
      </geometry>
    </visual>
    <collision>
      <geometry>
        <mesh filename="package://ada_description/meshes/forearm.dae"/>
      </geometry>
    </collision>
    <inertial>
      <mass value="0.6763"/>
      <origin xyz="0 0.081 -0.0086"/>
      <inertia ixx="0.0014202243190800001" ixy="0" ixz="0" iyy="0.000304335" iyz="0" izz="0.0014202243190800001"/>
    </inertial>
  </link>
  <joint name="j2n6s200_joint_3" type="revolute">
    <parent link="j2n6s200_link_2"/>
    <child link="j2n6s200_link_3"/>
    <axis xyz="0 0 1"/>
    <limit effort="40" lower="0.33161255787892263" upper="5.951572749300664" velocity="0.6283185307179586"/>
    <origin rpy="0 3.141592653589793 0" xyz="0 -0.410 0"/>
    <dynamics damping="0.0" friction="0.0"/>
  </joint>
  <transmission name="j2n6s200_joint_3_trans">
    <type>transmission_interface/SimpleTransmission</type>
    <joint name="j2n6s200_joint_3">
      <hardwareInterface>hardware_interface/EffortJointInterface</hardwareInterface>
    </joint>
    <actuator name="j2n6s200_joint_3_actuator">
      <hardwareInterface>hardware_interface/EffortJointInterface</hardwareInterface>
      <mechanicalReduction>160</mechanicalReduction>
    </actuator>
  </transmission>
  <!--For torque sensing in simulation-->
  <gazebo reference="j2n6s200_joint_3">
    <provideFeedback>true</provideFeedback>
  </gazebo>
  <gazebo>
    <plugin filename="libgazebo_ros_ft_sensor.so" name="ft_sensor">
      <updateRate>30.0</updateRate>
      <topicName>j2n6s200_joint_3_ft_sensor_topic</topicName>
      <jointName>j2n6s200_joint_3</jointName>
    </plugin>
  </gazebo>
  <link name="j2n6s200_link_4">
    <visual>
      <geometry>
        <mesh filename="package://ada_description/meshes/wrist.dae"/>
      </geometry>
      <material name="carbon_fiber">
        <color rgba="0.792156862745098 0.819607843137255 0.933333333333333 1"/>
      </material>
    </visual>
    <visual>
      <geometry>
        <mesh filename="package://ada_description/meshes/ring_small.dae"/>
      </geometry>
    </visual>
    <collision>
      <geometry>
        <mesh filename="package://ada_description/meshes/wrist.dae"/>
      </geometry>
    </collision>
    <inertial>
      <mass value="0.426367"/>
      <origin xyz="0 -0.037 -0.0642"/>
      <inertia ixx="7.734969059999999e-05" ixy="0" ixz="0" iyy="7.734969059999999e-05" iyz="0" izz="0.0001428"/>
    </inertial>
  </link>
  <joint name="j2n6s200_joint_4" type="continuous">
    <parent link="j2n6s200_link_3"/>
    <child link="j2n6s200_link_4"/>
    <axis xyz="0 0 1"/>
    <limit effort="20" velocity="0.8377580409572781"/>
    <origin rpy="-1.5707963267948966 0 3.141592653589793" xyz="0 0.2073 -0.0114"/>
    <dynamics damping="0.0" friction="0.0"/>
  </joint>
  <transmission name="j2n6s200_joint_4_trans">
    <type>transmission_interface/SimpleTransmission</type>
    <joint name="j2n6s200_joint_4">
      <hardwareInterface>hardware_interface/EffortJointInterface</hardwareInterface>
    </joint>
    <actuator name="j2n6s200_joint_4_actuator">
      <hardwareInterface>hardware_interface/EffortJointInterface</hardwareInterface>
      <mechanicalReduction>160</mechanicalReduction>
    </actuator>
  </transmission>
  <!--For torque sensing in simulation-->
  <gazebo reference="j2n6s200_joint_4">
    <provideFeedback>true</provideFeedback>
  </gazebo>
  <gazebo>
    <plugin filename="libgazebo_ros_ft_sensor.so" name="ft_sensor">
      <updateRate>30.0</updateRate>
      <topicName>j2n6s200_joint_4_ft_sensor_topic</topicName>
      <jointName>j2n6s200_joint_4</jointName>
    </plugin>
  </gazebo>
  <link name="j2n6s200_link_5">
    <visual>
      <geometry>
        <mesh filename="package://ada_description/meshes/wrist.dae"/>
      </geometry>
      <material name="carbon_fiber">
        <color rgba="0.792156862745098 0.819607843137255 0.933333333333333 1"/>
      </material>
    </visual>
    <visual>
      <geometry>
        <mesh filename="package://ada_description/meshes/ring_small.dae"/>
      </geometry>
    </visual>
    <collision>
      <geometry>
        <mesh filename="package://ada_description/meshes/wrist.dae"/>
      </geometry>
    </collision>
    <inertial>
      <mass value="0.426367"/>
      <origin xyz="0 -0.037 -0.0642"/>
      <inertia ixx="7.734969059999999e-05" ixy="0" ixz="0" iyy="7.734969059999999e-05" iyz="0" izz="0.0001428"/>
    </inertial>
  </link>
  <joint name="j2n6s200_joint_5" type="continuous">
    <parent link="j2n6s200_link_4"/>
    <child link="j2n6s200_link_5"/>
    <axis xyz="0 0 1"/>
    <limit effort="20" velocity="0.8377580409572781"/>
    <origin rpy="1.0471975511965976 0 3.141592653589793" xyz="0 -0.03703 -0.06414"/>
    <dynamics damping="0.0" friction="0.0"/>
  </joint>
  <transmission name="j2n6s200_joint_5_trans">
    <type>transmission_interface/SimpleTransmission</type>
    <joint name="j2n6s200_joint_5">
      <hardwareInterface>hardware_interface/EffortJointInterface</hardwareInterface>
    </joint>
    <actuator name="j2n6s200_joint_5_actuator">
      <hardwareInterface>hardware_interface/EffortJointInterface</hardwareInterface>
      <mechanicalReduction>160</mechanicalReduction>
    </actuator>
  </transmission>
  <!--For torque sensing in simulation-->
  <gazebo reference="j2n6s200_joint_5">
    <provideFeedback>true</provideFeedback>
  </gazebo>
  <gazebo>
    <plugin filename="libgazebo_ros_ft_sensor.so" name="ft_sensor">
      <updateRate>30.0</updateRate>
      <topicName>j2n6s200_joint_5_ft_sensor_topic</topicName>
      <jointName>j2n6s200_joint_5</jointName>
    </plugin>
  </gazebo>
  <link name="j2n6s200_link_6">
    <visual>
      <geometry>
        <mesh filename="package://ada_description/meshes/hand_2finger.dae"/>
      </geometry>
      <material name="carbon_fiber">
        <color rgba="0.792156862745098 0.819607843137255 0.933333333333333 1"/>
      </material>
    </visual>
    <visual>
      <geometry>
        <mesh filename="package://ada_description/meshes/ring_small.dae"/>
      </geometry>
    </visual>
    <collision>
      <geometry>
        <mesh filename="package://ada_description/meshes/hand_2finger.dae"/>
      </geometry>
    </collision>
    <inertial>
      <mass value="0.78"/>
      <origin xyz="0 0 -0.06"/>
      <inertia ixx="0.00037049851799999997" ixy="0" ixz="0" iyy="0.00037049851799999997" iyz="0" izz="0.0006240000000000001"/>
    </inertial>
  </link>
  <joint name="j2n6s200_joint_6" type="continuous">
    <parent link="j2n6s200_link_5"/>
    <child link="j2n6s200_link_6"/>
    <axis xyz="0 0 1"/>
    <limit effort="20" velocity="0.8377580409572781"/>
    <origin rpy="1.0471975511965976 0 3.141592653589793" xyz="0 -0.03703 -0.06414"/>
    <dynamics damping="0.0" friction="0.0"/>
  </joint>
  <transmission name="j2n6s200_joint_6_trans">
    <type>transmission_interface/SimpleTransmission</type>
    <joint name="j2n6s200_joint_6">
      <hardwareInterface>hardware_interface/EffortJointInterface</hardwareInterface>
    </joint>
    <actuator name="j2n6s200_joint_6_actuator">
      <hardwareInterface>hardware_interface/EffortJointInterface</hardwareInterface>
      <mechanicalReduction>160</mechanicalReduction>
    </actuator>
  </transmission>
  <!--For torque sensing in simulation-->
  <gazebo reference="j2n6s200_joint_6">
    <provideFeedback>true</provideFeedback>
  </gazebo>
  <gazebo>
    <plugin filename="libgazebo_ros_ft_sensor.so" name="ft_sensor">
      <updateRate>30.0</updateRate>
      <topicName>j2n6s200_joint_6_ft_sensor_topic</topicName>
      <jointName>j2n6s200_joint_6</jointName>
    </plugin>
  </gazebo>
  <link name="j2n6s200_end_effector"/>
  <joint name="j2n6s200_joint_end_effector" type="fixed">
    <parent link="j2n6s200_link_6"/>
    <child link="j2n6s200_end_effector"/>
    <axis xyz="0 0 0"/>
    <origin rpy="3.141592653589793 0 1.5707963267948966" xyz="0 0 -0.1600"/>
  </joint>
  <link name="j2n6s200_link_finger_1">
    <visual>
      <geometry>
        <mesh filename="package://ada_description/meshes/finger_proximal.dae"/>
      </geometry>
      <material name="carbon_fiber">
        <color rgba="0.792156862745098 0.819607843137255 0.933333333333333 1"/>
      </material>
    </visual>
    <collision>
      <geometry>
        <mesh filename="package://ada_description/meshes/finger_proximal.dae"/>
      </geometry>
    </collision>
    <inertial>
      <mass value="0.01"/>
      <origin xyz="0.022 0 0"/>
      <inertia ixx="7.8999684e-07" ixy="0" ixz="0" iyy="7.8999684e-07" iyz="0" izz="8e-08"/>
    </inertial>
  </link>
  <joint name="j2n6s200_joint_finger_1" type="revolute">
    <parent link="j2n6s200_link_6"/>
    <child link="j2n6s200_link_finger_1"/>
    <axis xyz="0 0 1"/>
    <origin rpy="-1.570796327 .649262481663582 1.57079632679490" xyz="-0.0025 0.03095 -0.11482"/>
    <limit effort="2" lower="0" upper="1.51" velocity="1"/>
  </joint>
  <transmission name="j2n6s200_joint_finger_1_trans">
    <type>transmission_interface/SimpleTransmission</type>
    <joint name="j2n6s200_joint_finger_1">
      <hardwareInterface>hardware_interface/EffortJointInterface</hardwareInterface>
    </joint>
    <actuator name="j2n6s200_joint_finger_1_actuator">
      <hardwareInterface>hardware_interface/EffortJointInterface</hardwareInterface>
      <mechanicalReduction>1</mechanicalReduction>
    </actuator>
  </transmission>
  <link name="j2n6s200_link_finger_tip_1">
    <visual>
      <geometry>
        <mesh filename="package://ada_description/meshes/finger_distal.dae"/>
      </geometry>
      <material name="carbon_fiber">
        <color rgba="0.792156862745098 0.819607843137255 0.933333333333333 1"/>
      </material>
    </visual>
    <collision>
      <geometry>
        <mesh filename="package://ada_description/meshes/finger_distal.dae"/>
      </geometry>
    </collision>
    <inertial>
      <mass value="0.01"/>
      <origin xyz="0.022 0 0"/>
      <inertia ixx="7.8999684e-07" ixy="0" ixz="0" iyy="7.8999684e-07" iyz="0" izz="8e-08"/>
    </inertial>
  </link>
  <joint name="j2n6s200_joint_finger_tip_1" type="fixed">
    <parent link="j2n6s200_link_finger_1"/>
    <child link="j2n6s200_link_finger_tip_1"/>
    <axis xyz="0 0 1"/>
    <origin rpy="0 0 0" xyz="0.044 -0.003 0"/>
    <limit effort="2" lower="0" upper="2" velocity="1"/>
  </joint>
  <transmission name="j2n6s200_joint_finger_tip_1_trans">
    <type>transmission_interface/SimpleTransmission</type>
    <joint name="j2n6s200_joint_finger_tip_1">
      <hardwareInterface>hardware_interface/EffortJointInterface</hardwareInterface>
    </joint>
    <actuator name="j2n6s200_joint_finger_tip_1_actuator">
      <hardwareInterface>hardware_interface/EffortJointInterface</hardwareInterface>
      <mechanicalReduction>1</mechanicalReduction>
    </actuator>
  </transmission>
  <link name="j2n6s200_link_finger_2">
    <visual>
      <geometry>
        <mesh filename="package://ada_description/meshes/finger_proximal.dae"/>
      </geometry>
      <material name="carbon_fiber">
        <color rgba="0.792156862745098 0.819607843137255 0.933333333333333 1"/>
      </material>
    </visual>
    <collision>
      <geometry>
        <mesh filename="package://ada_description/meshes/finger_proximal.dae"/>
      </geometry>
    </collision>
    <inertial>
      <mass value="0.01"/>
      <origin xyz="0.022 0 0"/>
      <inertia ixx="7.8999684e-07" ixy="0" ixz="0" iyy="7.8999684e-07" iyz="0" izz="8e-08"/>
    </inertial>
  </link>
  <joint name="j2n6s200_joint_finger_2" type="revolute">
    <parent link="j2n6s200_link_6"/>
    <child link="j2n6s200_link_finger_2"/>
    <axis xyz="0 0 1"/>
    <origin rpy="-1.570796327 .649262481663582 -1.57079632679490" xyz="-0.0025 -0.03095 -0.11482"/>
    <limit effort="2" lower="0" upper="1.51" velocity="1"/>
  </joint>
  <transmission name="j2n6s200_joint_finger_2_trans">
    <type>transmission_interface/SimpleTransmission</type>
    <joint name="j2n6s200_joint_finger_2">
      <hardwareInterface>hardware_interface/EffortJointInterface</hardwareInterface>
    </joint>
    <actuator name="j2n6s200_joint_finger_2_actuator">
      <hardwareInterface>hardware_interface/EffortJointInterface</hardwareInterface>
      <mechanicalReduction>1</mechanicalReduction>
    </actuator>
  </transmission>
  <link name="j2n6s200_link_finger_tip_2">
    <visual>
      <geometry>
        <mesh filename="package://ada_description/meshes/finger_distal.dae"/>
      </geometry>
      <material name="carbon_fiber">
        <color rgba="0.792156862745098 0.819607843137255 0.933333333333333 1"/>
      </material>
    </visual>
    <collision>
      <geometry>
        <mesh filename="package://ada_description/meshes/finger_distal.dae"/>
      </geometry>
    </collision>
    <inertial>
      <mass value="0.01"/>
      <origin xyz="0.022 0 0"/>
      <inertia ixx="7.8999684e-07" ixy="0" ixz="0" iyy="7.8999684e-07" iyz="0" izz="8e-08"/>
    </inertial>
  </link>
  <joint name="j2n6s200_joint_finger_tip_2" type="fixed">
    <parent link="j2n6s200_link_finger_2"/>
    <child link="j2n6s200_link_finger_tip_2"/>
    <axis xyz="0 0 1"/>
    <origin rpy="0 0 0" xyz="0.044 -0.003 0"/>
    <limit effort="2" lower="0" upper="2" velocity="1"/>
  </joint>
  <transmission name="j2n6s200_joint_finger_tip_2_trans">
    <type>transmission_interface/SimpleTransmission</type>
    <joint name="j2n6s200_joint_finger_tip_2">
      <hardwareInterface>hardware_interface/EffortJointInterface</hardwareInterface>
    </joint>
    <actuator name="j2n6s200_joint_finger_tip_2_actuator">
      <hardwareInterface>hardware_interface/EffortJointInterface</hardwareInterface>
      <mechanicalReduction>1</mechanicalReduction>
    </actuator>
  </transmission>
  <link name="nanoMount">
    <visual>
      <geometry>
        <mesh filename="package://ada_description/meshes/camera/2023_03_09_nanoArmMount.stl" scale="0.001 0.001 0.001"/>
      </geometry>
      <material name="abs">
        <color rgba="0.4 0.4 0.4 1"/>
      </material>
    </visual>
    <collision>
      <geometry>
        <mesh filename="package://ada_description/meshes/camera/2023_03_09_nanoArmMount.stl" scale="0.001 0.001 0.001"/>
      </geometry>
    </collision>
    <inertial>
      <origin rpy="0 0 0" xyz="-0.002400 0.0046958 0.0115245"/>
      <mass value="0.008"/>
      <inertia ixx="0.00000095025" ixy="-0.000000297842" ixz="-0.00000000010444" iyy="0.0000067325" iyz="0.000000000470196" izz="0.0000069433"/>
    </inertial>
  </link>
  <joint name="nanoMount_to_world" type="fixed">
    <parent link="j2n6s200_link_6"/>
    <child link="nanoMount"/>
    <axis xyz="0 0 1"/>
    <origin rpy="4.71238898038469 0 4.71238898038469" xyz="0.0165 0 0.0011"/>
  </joint>
  <link name="enclosureBottom">
    <visual>
      <geometry>
        <mesh filename="package://ada_description/meshes/camera/2023_09_28_nanoEnclosureBottom.stl" scale="0.001 0.001 0.001"/>
      </geometry>
      <material name="abs">
        <color rgba="0.4 0.4 0.4 1"/>
      </material>
    </visual>
    <collision>
      <geometry>
        <mesh filename="package://ada_description/meshes/camera/2023_09_28_nanoEnclosureBottom.stl" scale="0.001 0.001 0.001"/>
      </geometry>
    </collision>
    <inertial>
      <origin rpy="0 0 0" xyz="0.0546451 0.0472161 0.00043655"/>
      <mass value="0.04"/>
      <inertia ixx="0.000041028" ixy="-0.000000324" ixz="-0.00000045367" iyy="0.000083168" iyz="0.0000026243" izz="0.000116424"/>
    </inertial>
  </link>
  <joint name="enclosureBottom_to_nanoMount" type="fixed">
    <parent link="nanoMount"/>
    <child link="enclosureBottom"/>
    <axis xyz="0 0 1"/>
    <origin rpy="0 0 1.5707963267948966" xyz="0.0412 -0.0218 0.026"/>
  </joint>
  <link name="nano">
    <visual>
      <geometry>
        <mesh filename="package://ada_description/meshes/camera/2023_03_21_jetsonNano.stl" scale="0.001 0.001 0.001"/>
      </geometry>
      <material name="abs">
        <color rgba="0.4 0.4 0.4 1"/>
      </material>
    </visual>
    <collision>
      <geometry>
        <mesh filename="package://ada_description/meshes/camera/2023_03_21_jetsonNano.stl" scale="0.001 0.001 0.001"/>
      </geometry>
    </collision>
    <inertial>
      <origin rpy="0 0 0" xyz="0.0435615 0.02502709 0.0091247"/>
      <mass value="0.142"/>
      <inertia ixx="0.000077456" ixy="-0.000004935" ixz="0.0000015461" iyy="0.0001013" iyz="0.0000036951" izz="0.0001727"/>
    </inertial>
  </link>
  <joint name="nano_to_enclosureBottom" type="fixed">
    <parent link="enclosureBottom"/>
    <child link="nano"/>
    <axis xyz="0 0 1"/>
    <origin rpy="0 0 0" xyz="0.0105 0.014 -0.0015"/>
  </joint>
  <link name="frontStabilizer">
    <visual>
      <geometry>
        <mesh filename="package://ada_description/meshes/camera/2023_09_21_nanoEnclosureFrontStabilizer.stl" scale="0.001 0.001 0.001"/>
      </geometry>
      <material name="abs">
        <color rgba="0.4 0.4 0.4 1"/>
      </material>
    </visual>
    <collision>
      <geometry>
        <mesh filename="package://ada_description/meshes/camera/2023_09_21_nanoEnclosureFrontStabilizer.stl" scale="0.001 0.001 0.001"/>
      </geometry>
    </collision>
    <inertial>
      <origin rpy="0 0 0" xyz="-0.008107 -0.000955 0.02045"/>
      <mass value="0.0198"/>
      <inertia ixx="0.00000074776" ixy="0.000000000071856" ixz="0.0000000002764" iyy="0.0000118843" iyz="0.00000001021778" izz="0.0000119096"/>
    </inertial>
  </link>
  <joint name="frontStabilizer_to_enclosureBottom" type="fixed">
    <parent link="enclosureBottom"/>
    <child link="frontStabilizer"/>
    <axis xyz="0 0 1"/>
    <origin rpy="0 0 1.5707963267948966" xyz="0.1063 0.0493 -0.0363"/>
  </joint>
  <link name="enclosureTop">
    <visual>
      <geometry>
        <mesh filename="package://ada_description/meshes/camera/2023_06_06_nanoEnclosureTopCameraBack.stl" scale="0.001 0.001 0.001"/>
      </geometry>
      <material name="abs">
        <color rgba="0.4 0.4 0.4 1"/>
      </material>
    </visual>
    <collision>
      <geometry>
        <mesh filename="package://ada_description/meshes/camera/2023_06_06_nanoEnclosureTopCameraBack.stl" scale="0.001 0.001 0.001"/>
      </geometry>
    </collision>
    <inertial>
      <origin rpy="0 0 0" xyz="0.041228 0.006275 0.016379"/>
      <mass value="0.046"/>
      <inertia ixx="0.00005942" ixy="-0.000000046193" ixz="0.0000091699" iyy="0.000085611" iyz="0.0000012783" izz="0.000126390"/>
    </inertial>
  </link>
  <joint name="enclosureTop_to_enclosureBottom" type="fixed">
    <parent link="enclosureBottom"/>
    <child link="enclosureTop"/>
    <axis xyz="0 0 1"/>
    <origin rpy="0 2.886774582798621 3.141592653589793" xyz="0.009925 0.04099 0.05442"/>
  </joint>
  <link name="cameraMount">
    <visual>
      <geometry>
        <mesh filename="package://ada_description/meshes/camera/2023_06_06_cameraBackMount.stl" scale="0.001 0.001 0.001"/>
      </geometry>
      <material name="abs">
        <color rgba="0.4 0.4 0.4 1"/>
      </material>
    </visual>
    <collision>
      <geometry>
        <mesh filename="package://ada_description/meshes/camera/2023_06_06_cameraBackMount.stl" scale="0.001 0.001 0.001"/>
      </geometry>
    </collision>
    <inertial>
      <origin rpy="0 0 0" xyz="-0.007986 0 0.010064"/>
      <mass value="0.004"/>
      <inertia ixx="0.000002782" ixy="-0.00000000002321" ixz="0.000000074385" iyy="00.0000005528" iyz="-0.00000000000178" izz="0.000002964"/>
    </inertial>
  </link>
  <joint name="cameraMount_to_enclosureTop" type="fixed">
    <parent link="enclosureTop"/>
    <child link="cameraMount"/>
    <axis xyz="0 0 1"/>
    <origin rpy="0 1.5707963267948966 0" xyz="-0.0132 0 -0.022"/>
  </joint>
  <link name="screwHeadLeft">
    <visual>
      <geometry>
        <mesh filename="package://ada_description/meshes/camera/2023_11_07_screwHead.stl" scale="0.001 0.001 0.001"/>
      </geometry>
      <material name="abs">
        <color rgba="0.4 0.4 0.4 1"/>
      </material>
    </visual>
    <collision>
      <geometry>
        <mesh filename="package://ada_description/meshes/camera/2023_11_07_screwHead.stl" scale="0.001 0.001 0.001"/>
      </geometry>
    </collision>
    <inertial>
      <origin rpy="0 0 0" xyz="0 0 0.0015"/>
      <mass value="0.0001"/>
      <inertia ixx="0.000000000342785" ixy="0" ixz="0" iyy="0.000000000342785" iyz="0" izz="0.000000000543538"/>
    </inertial>
  </link>
  <joint name="screwHeadLeft_to_cameraMount" type="fixed">
    <parent link="cameraMount"/>
    <child link="screwHeadLeft"/>
    <axis xyz="0 0 1"/>
    <origin rpy="3.141592653589793 0 0" xyz="0.0165 -0.0225 0"/>
  </joint>
  <link name="screwHeadRight">
    <visual>
      <geometry>
        <mesh filename="package://ada_description/meshes/camera/2023_11_07_screwHead.stl" scale="0.001 0.001 0.001"/>
      </geometry>
      <material name="abs">
        <color rgba="0.4 0.4 0.4 1"/>
      </material>
    </visual>
    <collision>
      <geometry>
        <mesh filename="package://ada_description/meshes/camera/2023_11_07_screwHead.stl" scale="0.001 0.001 0.001"/>
      </geometry>
    </collision>
    <inertial>
      <origin rpy="0 0 0" xyz="0 0 0.0015"/>
      <mass value="0.0001"/>
      <inertia ixx="0.000000000342785" ixy="0" ixz="0" iyy="0.000000000342785" iyz="0" izz="0.000000000543538"/>
    </inertial>
  </link>
  <joint name="screwHeadRight_to_cameraMount" type="fixed">
    <parent link="cameraMount"/>
    <child link="screwHeadRight"/>
    <axis xyz="0 0 1"/>
    <origin rpy="3.141592653589793 0 0" xyz="0.0165 0.0225 0"/>
  </joint>
  <!-- camera body, with origin at bottom screw mount -->
  <joint name="uncalibrated_camera_joint" type="fixed">
    <origin rpy="0 -1.5707963267948966 3.141592653589793" xyz="0.006 0 0.013"/>
    <parent link="cameraMount"/>
    <child link="uncalibrated_camera_bottom_screw_frame"/>
  </joint>
  <link name="uncalibrated_camera_bottom_screw_frame"/>
  <joint name="uncalibrated_camera_link_joint" type="fixed">
    <origin rpy="0 0 0" xyz="0 0.02 0.0115"/>
    <parent link="uncalibrated_camera_bottom_screw_frame"/>
    <child link="uncalibrated_camera_link"/>
  </joint>
  <link name="uncalibrated_camera_link">
    <visual>
      <origin rpy="1.5707963267948966 0 1.5707963267948966" xyz="0.00987 -0.02 0"/>
      <geometry>
        <mesh filename="package://ada_description/meshes/camera/d415.stl"/>
      </geometry>
      <material name="aluminum"/>
    </visual>
    <collision>
      <origin rpy="0 0 0" xyz="0 -0.02 0"/>
      <geometry>
        <box size="0.02005 0.099 0.023"/>
      </geometry>
    </collision>
    <inertial>
      <mass value="0.0589"/>
      <!-- manufacturer's value: 0.072 -->
      <origin xyz="0 -0.02 0"/>
      <inertia ixx="0.00005491" ixy="-0.0000000249492" ixz="0.00000004862028" iyy="0.00000521068" iyz="0.00000000857625" izz="0.0000554597"/>
    </inertial>
  </link>
  <!-- Hard-coded Extrinsics -->
  <link name="camera_link"/>
  <joint name="extrinsics" type="fixed">
    <origin rpy="0.17234 -1.56127 2.96967" xyz="0.0194 -0.01606 0.029014"/>
    <parent link="cameraMount"/>
    <child link="camera_link"/>
  </joint>
  <!-- Copy Realsense in case of simulation -->
  <!--
  <link name="camera_color_optical_frame" />
  <joint name="optical_republish" type="fixed">
    <origin xyz="0.000 -0.015 0.000" rpy="-1.564 0.000 -1.573" />
    <parent link="camera_link" />
    <child link="camera_color_optical_frame" />
  </joint>
  -->
  <link name="FTArmMount">
    <visual>
      <geometry>
        <mesh filename="package://ada_description/meshes/forque/2024_01_18_FTArmMount.stl" scale="0.001 0.001 0.001"/>
      </geometry>
      <material name="abs">
        <color rgba="0.4 0.4 0.4 1"/>
      </material>
    </visual>
    <collision>
      <geometry>
        <mesh filename="package://ada_description/meshes/forque/2024_01_18_FTArmMount.stl" scale="0.001 0.001 0.001"/>
      </geometry>
    </collision>
    <inertial>
      <origin rpy="0 0 0" xyz="0.010957 -0.019223 -0.03777"/>
      <mass value="0.03783"/>
      <inertia ixx="0.000018817" ixy="-0.0000003327" ixz="-0.000000092476" iyy="0.00001119989" iyz="-0.00000120296" izz="0.000026883"/>
    </inertial>
  </link>
  <joint name="FTArmMount_to_arm" type="fixed">
    <parent link="j2n6s200_link_6"/>
    <child link="FTArmMount"/>
    <axis xyz="0 0 1"/>
    <origin rpy="1.5707963267948966 0 1.5707963267948966" xyz="0.0065 -0.011 -0.0075"/>
  </joint>
</robot>
